<?xml version="1.0" encoding="utf-8"?>
<!-- =================================================================================== -->
<!-- |    This document was autogenerated by xacro from flowerbot.urdf.xacro           | -->
<!-- |    EDITING THIS FILE BY HAND IS NOT RECOMMENDED                                 | -->
<!-- =================================================================================== -->
<robot name="flowerbot" xmlns:xacro="http://ros.org/wiki/xacro">
  <link name="base_footprint"/>
  <joint name="base_joint" type="fixed">
    <origin rpy="0 0 0" xyz="0 0 0.335722"/>
    <parent link="base_footprint"/>
    <child link="base_link"/>
  </joint>
  <gazebo reference="base_link">
    <mu1>0</mu1>
    <mu2>0</mu2>
    <material>Gazebo/Grey</material>
  </gazebo>
  <link name="base_link">
    <inertial>
      <origin rpy="0 0 0" xyz="0 0.0751835052567173 0.414272"/>
      <mass value="8.95683313242359"/>
      <inertia ixx="-0.000003" ixy="0.997477" ixz="-0.070991" iyy="-0.000003" iyz="-0.000007" izz="0.997477"/>
    </inertial>
    <visual>
      <origin rpy="0 0 0" xyz="0 0 0"/>
      <geometry>
        <mesh filename="package://flowerbot_description/meshes/frame_link.STL"/>
      </geometry>
      <material name="material_blue"/>
    </visual>
    <collision>
      <origin rpy="0 0 0" xyz="0 0 0"/>
      <geometry>
        <mesh filename="package://flowerbot_description/meshes/frame_link.STL"/>
      </geometry>
    </collision>
  </link>
  <gazebo reference="wheel0_suspension_link">
    <mu1>0</mu1>
    <mu2>0</mu2>
    <kp>1000000.0</kp>
    <kd>100.0</kd>
    <material>Gazebo/Blue</material>
  </gazebo>
  <link name="wheel0_suspension_link">
    <inertial>
      <origin rpy="0 0 0" xyz="-0.033779  -0.000046 -0.112357"/>
      <mass value="0.27606"/>
      <inertia ixx="0.058272" ixy="-0.000542" ixz="0.998301" iyy="0.001418" iyz="-0.058272" izz="0.000624"/>
    </inertial>
    <visual>
      <origin rpy="0 0 0" xyz="0 0 0"/>
      <geometry>
        <mesh filename="package://flowerbot_description/meshes/suspension_link.STL"/>
      </geometry>
      <material name="material_blue"/>
    </visual>
    <collision>
      <origin rpy="0 0 0" xyz="0 0 0"/>
      <geometry>
        <mesh filename="package://flowerbot_description/meshes/suspension_link.STL"/>
      </geometry>
    </collision>
  </link>
  <joint name="wheel0_suspension_joint" type="fixed">
    <origin rpy="0 0 3.14159265359" xyz="0.3048 -0.29195 0.21"/>
    <parent link="base_link"/>
    <child link="wheel0_suspension_link"/>
  </joint>
  <gazebo reference="wheel0_steering_link">
    <mu1>0</mu1>
    <mu2>0</mu2>
    <kp>1000000.0</kp>
    <kd>100.0</kd>
    <material>Gazebo/Orange</material>
  </gazebo>
  <gazebo reference="wheel0_steering_arm_link">
    <mu1>0</mu1>
    <mu2>0</mu2>
    <kp>1000000.0</kp>
    <kd>100.0</kd>
    <material>Gazebo/Orange</material>
  </gazebo>
  <gazebo reference="wheel0_wheel_link">
    <mu1>1</mu1>
    <mu2>1</mu2>
    <kp>1000000.0</kp>
    <kd>100.0</kd>
    <material>Gazebo/Black</material>
  </gazebo>
  <link name="wheel0_steering_arm_link">
    <inertial>
      <origin rpy="0 0 0" xyz="-0.000033 -0.059005  -0.107760"/>
      <mass value="0.64615"/>
      <inertia ixx="-0.00075" ixy="0.234166" ixz="0.972196" iyy="-0.972192" iyz="0.234167" izz="0.00008"/>
    </inertial>
    <visual>
      <origin rpy="0 0 0" xyz="0 0 0"/>
      <geometry>
        <mesh filename="package://flowerbot_description/meshes/steering_arm_link.STL"/>
      </geometry>
      <material name="material_orange"/>
    </visual>
    <collision>
      <origin rpy="0 0 0" xyz="0 0 0"/>
      <geometry>
        <mesh filename="package://flowerbot_description/meshes/steering_arm_link.STL"/>
      </geometry>
    </collision>
  </link>
  <link name="wheel0_steering_link">
    <inertial>
      <origin rpy="0 0 0" xyz="0.004891 0 0.053105"/>
      <mass value="0.49153"/>
      <inertia ixx="-0.004791" ixy="0" ixz="0.999989" iyy="0.000" iyz="0.004791" izz="0"/>
    </inertial>
    <visual>
      <origin rpy="0 0 0" xyz="0 0 0"/>
      <geometry>
        <mesh filename="package://flowerbot_description/meshes/steering_link.STL"/>
      </geometry>
      <material name="material_orange"/>
    </visual>
    <collision>
      <origin rpy="0 0 0" xyz="0 0 0"/>
      <geometry>
        <mesh filename="package://flowerbot_description/meshes/steering_link.STL"/>
      </geometry>
    </collision>
  </link>
  <joint name="wheel0_steering_joint" type="revolute">
    <origin rpy="0 0 3.14159265359" xyz="0 0 -0.001"/>
    <parent link="wheel0_steering_link"/>
    <child link="wheel0_steering_arm_link"/>
    <axis xyz="0 0 1"/>
    <limit effort="0" lower="-1.57079632679" upper="1.57079632679" velocity="1"/>
    <safety_controller k_velocity="0"/>
  </joint>
  <transmission name="wheel0_steering_joint_control">
    <type>transmission_interface/SimpleTransmission</type>
    <joint name="wheel0_steering_joint">
      <hardwareInterface>hardware_interface/EffortJointInterface</hardwareInterface>
    </joint>
    <actuator name="wheel0_steering_joint_motor">
      <hardwareInterface>hardware_interface/EffortJointInterface</hardwareInterface>
      <mechanicalReduction>504</mechanicalReduction>
    </actuator>
  </transmission>
  <joint name="wheel0_wheel_modular_joint" type="fixed">
    <origin rpy="0 0 0" xyz="-0.142143 0 -0.229872"/>
    <parent link="wheel0_suspension_link"/>
    <child link="wheel0_steering_link"/>
  </joint>
  <link name="wheel0_wheel_link">
    <inertial>
      <origin rpy="0 0 0" xyz="0 0 0.000083"/>
      <mass value="3.2532"/>
      <inertia ixx="0.999544" ixy="-0.030190" ixz="0.000003" iyy="0.999544" iyz="0.000095" izz="1.0"/>
    </inertial>
    <visual>
      <origin rpy="0 0 0" xyz="0 0 0"/>
      <geometry>
        <mesh filename="package://flowerbot_description/meshes/wheel_link.STL"/>
      </geometry>
      <material name="material_black"/>
    </visual>
    <collision>
      <origin rpy="0 0 0" xyz="0 0 0"/>
      <geometry>
        <mesh filename="package://flowerbot_description/meshes/wheel_link.STL"/>
      </geometry>
    </collision>
  </link>
  <joint name="wheel0_driving_joint" type="continuous">
    <origin rpy="-1.57079632679 0 0" xyz="0 0.007981 -0.18"/>
    <parent link="wheel0_steering_arm_link"/>
    <child link="wheel0_wheel_link"/>
    <axis xyz="0 -1 0"/>
    <safety_controller k_velocity="5"/>
  </joint>
  <transmission name="wheel0_driving_joint_control">
    <type>transmission_interface/SimpleTransmission</type>
    <joint name="wheel0_driving_joint">
      <hardwareInterface>hardware_interface/EffortJointInterface</hardwareInterface>
    </joint>
    <actuator name="wheel0_driving_joint_motor">
      <hardwareInterface>hardware_interface/EffortJointInterface</hardwareInterface>
      <mechanicalReduction>84</mechanicalReduction>
    </actuator>
  </transmission>
  <gazebo reference="wheel1_suspension_link">
    <mu1>0</mu1>
    <mu2>0</mu2>
    <kp>1000000.0</kp>
    <kd>100.0</kd>
    <material>Gazebo/Blue</material>
  </gazebo>
  <link name="wheel1_suspension_link">
    <inertial>
      <origin rpy="0 0 0" xyz="-0.033779  -0.000046 -0.112357"/>
      <mass value="0.27606"/>
      <inertia ixx="0.058272" ixy="-0.000542" ixz="0.998301" iyy="0.001418" iyz="-0.058272" izz="0.000624"/>
    </inertial>
    <visual>
      <origin rpy="0 0 0" xyz="0 0 0"/>
      <geometry>
        <mesh filename="package://flowerbot_description/meshes/suspension_link.STL"/>
      </geometry>
      <material name="material_blue"/>
    </visual>
    <collision>
      <origin rpy="0 0 0" xyz="0 0 0"/>
      <geometry>
        <mesh filename="package://flowerbot_description/meshes/suspension_link.STL"/>
      </geometry>
    </collision>
  </link>
  <joint name="wheel1_suspension_joint" type="fixed">
    <origin rpy="0 0 3.14159265359" xyz="0.3048 0.29195 0.21"/>
    <parent link="base_link"/>
    <child link="wheel1_suspension_link"/>
  </joint>
  <gazebo reference="wheel1_steering_link">
    <mu1>0</mu1>
    <mu2>0</mu2>
    <kp>1000000.0</kp>
    <kd>100.0</kd>
    <material>Gazebo/Orange</material>
  </gazebo>
  <gazebo reference="wheel1_steering_arm_link">
    <mu1>0</mu1>
    <mu2>0</mu2>
    <kp>1000000.0</kp>
    <kd>100.0</kd>
    <material>Gazebo/Orange</material>
  </gazebo>
  <gazebo reference="wheel1_wheel_link">
    <mu1>1</mu1>
    <mu2>1</mu2>
    <kp>1000000.0</kp>
    <kd>100.0</kd>
    <material>Gazebo/Black</material>
  </gazebo>
  <link name="wheel1_steering_arm_link">
    <inertial>
      <origin rpy="0 0 0" xyz="-0.000033 -0.059005  -0.107760"/>
      <mass value="0.64615"/>
      <inertia ixx="-0.00075" ixy="0.234166" ixz="0.972196" iyy="-0.972192" iyz="0.234167" izz="0.00008"/>
    </inertial>
    <visual>
      <origin rpy="0 0 0" xyz="0 0 0"/>
      <geometry>
        <mesh filename="package://flowerbot_description/meshes/steering_arm_link.STL"/>
      </geometry>
      <material name="material_orange"/>
    </visual>
    <collision>
      <origin rpy="0 0 0" xyz="0 0 0"/>
      <geometry>
        <mesh filename="package://flowerbot_description/meshes/steering_arm_link.STL"/>
      </geometry>
    </collision>
  </link>
  <link name="wheel1_steering_link">
    <inertial>
      <origin rpy="0 0 0" xyz="0.004891 0 0.053105"/>
      <mass value="0.49153"/>
      <inertia ixx="-0.004791" ixy="0" ixz="0.999989" iyy="0.000" iyz="0.004791" izz="0"/>
    </inertial>
    <visual>
      <origin rpy="0 0 0" xyz="0 0 0"/>
      <geometry>
        <mesh filename="package://flowerbot_description/meshes/steering_link.STL"/>
      </geometry>
      <material name="material_orange"/>
    </visual>
    <collision>
      <origin rpy="0 0 0" xyz="0 0 0"/>
      <geometry>
        <mesh filename="package://flowerbot_description/meshes/steering_link.STL"/>
      </geometry>
    </collision>
  </link>
  <joint name="wheel1_steering_joint" type="revolute">
    <origin rpy="0 0 0" xyz="0 0 -0.001"/>
    <parent link="wheel1_steering_link"/>
    <child link="wheel1_steering_arm_link"/>
    <axis xyz="0 0 1"/>
    <limit effort="0" lower="-1.57079632679" upper="1.57079632679" velocity="1"/>
    <safety_controller k_velocity="0"/>
  </joint>
  <transmission name="wheel1_steering_joint_control">
    <type>transmission_interface/SimpleTransmission</type>
    <joint name="wheel1_steering_joint">
      <hardwareInterface>hardware_interface/EffortJointInterface</hardwareInterface>
    </joint>
    <actuator name="wheel1_steering_joint_motor">
      <hardwareInterface>hardware_interface/EffortJointInterface</hardwareInterface>
      <mechanicalReduction>504</mechanicalReduction>
    </actuator>
  </transmission>
  <joint name="wheel1_wheel_modular_joint" type="fixed">
    <origin rpy="0 0 0" xyz="-0.142143 0 -0.229872"/>
    <parent link="wheel1_suspension_link"/>
    <child link="wheel1_steering_link"/>
  </joint>
  <link name="wheel1_wheel_link">
    <inertial>
      <origin rpy="0 0 0" xyz="0 0 0.000083"/>
      <mass value="3.2532"/>
      <inertia ixx="0.999544" ixy="-0.030190" ixz="0.000003" iyy="0.999544" iyz="0.000095" izz="1.0"/>
    </inertial>
    <visual>
      <origin rpy="0 0 0" xyz="0 0 0"/>
      <geometry>
        <mesh filename="package://flowerbot_description/meshes/wheel_link.STL"/>
      </geometry>
      <material name="material_black"/>
    </visual>
    <collision>
      <origin rpy="0 0 0" xyz="0 0 0"/>
      <geometry>
        <mesh filename="package://flowerbot_description/meshes/wheel_link.STL"/>
      </geometry>
    </collision>
  </link>
  <joint name="wheel1_driving_joint" type="continuous">
    <origin rpy="-1.57079632679 0 0" xyz="0 0.007981 -0.18"/>
    <parent link="wheel1_steering_arm_link"/>
    <child link="wheel1_wheel_link"/>
    <axis xyz="0 -1 0"/>
    <safety_controller k_velocity="5"/>
  </joint>
  <transmission name="wheel1_driving_joint_control">
    <type>transmission_interface/SimpleTransmission</type>
    <joint name="wheel1_driving_joint">
      <hardwareInterface>hardware_interface/EffortJointInterface</hardwareInterface>
    </joint>
    <actuator name="wheel1_driving_joint_motor">
      <hardwareInterface>hardware_interface/EffortJointInterface</hardwareInterface>
      <mechanicalReduction>84</mechanicalReduction>
    </actuator>
  </transmission>
  <gazebo reference="wheel2_suspension_link">
    <mu1>0</mu1>
    <mu2>0</mu2>
    <kp>1000000.0</kp>
    <kd>100.0</kd>
    <material>Gazebo/Blue</material>
  </gazebo>
  <link name="wheel2_suspension_link">
    <inertial>
      <origin rpy="0 0 0" xyz="-0.033779  -0.000046 -0.112357"/>
      <mass value="0.27606"/>
      <inertia ixx="0.058272" ixy="-0.000542" ixz="0.998301" iyy="0.001418" iyz="-0.058272" izz="0.000624"/>
    </inertial>
    <visual>
      <origin rpy="0 0 0" xyz="0 0 0"/>
      <geometry>
        <mesh filename="package://flowerbot_description/meshes/suspension_link.STL"/>
      </geometry>
      <material name="material_blue"/>
    </visual>
    <collision>
      <origin rpy="0 0 0" xyz="0 0 0"/>
      <geometry>
        <mesh filename="package://flowerbot_description/meshes/suspension_link.STL"/>
      </geometry>
    </collision>
  </link>
  <joint name="wheel2_suspension_joint" type="fixed">
    <origin rpy="0 0 0" xyz="-0.3048 0.29195 0.21"/>
    <parent link="base_link"/>
    <child link="wheel2_suspension_link"/>
  </joint>
  <gazebo reference="wheel2_steering_link">
    <mu1>0</mu1>
    <mu2>0</mu2>
    <kp>1000000.0</kp>
    <kd>100.0</kd>
    <material>Gazebo/Orange</material>
  </gazebo>
  <gazebo reference="wheel2_steering_arm_link">
    <mu1>0</mu1>
    <mu2>0</mu2>
    <kp>1000000.0</kp>
    <kd>100.0</kd>
    <material>Gazebo/Orange</material>
  </gazebo>
  <gazebo reference="wheel2_wheel_link">
    <mu1>1</mu1>
    <mu2>1</mu2>
    <kp>1000000.0</kp>
    <kd>100.0</kd>
    <material>Gazebo/Black</material>
  </gazebo>
  <link name="wheel2_steering_arm_link">
    <inertial>
      <origin rpy="0 0 0" xyz="-0.000033 -0.059005  -0.107760"/>
      <mass value="0.64615"/>
      <inertia ixx="-0.00075" ixy="0.234166" ixz="0.972196" iyy="-0.972192" iyz="0.234167" izz="0.00008"/>
    </inertial>
    <visual>
      <origin rpy="0 0 0" xyz="0 0 0"/>
      <geometry>
        <mesh filename="package://flowerbot_description/meshes/steering_arm_link.STL"/>
      </geometry>
      <material name="material_orange"/>
    </visual>
    <collision>
      <origin rpy="0 0 0" xyz="0 0 0"/>
      <geometry>
        <mesh filename="package://flowerbot_description/meshes/steering_arm_link.STL"/>
      </geometry>
    </collision>
  </link>
  <link name="wheel2_steering_link">
    <inertial>
      <origin rpy="0 0 0" xyz="0.004891 0 0.053105"/>
      <mass value="0.49153"/>
      <inertia ixx="-0.004791" ixy="0" ixz="0.999989" iyy="0.000" iyz="0.004791" izz="0"/>
    </inertial>
    <visual>
      <origin rpy="0 0 0" xyz="0 0 0"/>
      <geometry>
        <mesh filename="package://flowerbot_description/meshes/steering_link.STL"/>
      </geometry>
      <material name="material_orange"/>
    </visual>
    <collision>
      <origin rpy="0 0 0" xyz="0 0 0"/>
      <geometry>
        <mesh filename="package://flowerbot_description/meshes/steering_link.STL"/>
      </geometry>
    </collision>
  </link>
  <joint name="wheel2_steering_joint" type="revolute">
    <origin rpy="0 0 3.14159265359" xyz="0 0 -0.001"/>
    <parent link="wheel2_steering_link"/>
    <child link="wheel2_steering_arm_link"/>
    <axis xyz="0 0 1"/>
    <limit effort="0" lower="-1.57079632679" upper="1.57079632679" velocity="1"/>
    <safety_controller k_velocity="0"/>
  </joint>
  <transmission name="wheel2_steering_joint_control">
    <type>transmission_interface/SimpleTransmission</type>
    <joint name="wheel2_steering_joint">
      <hardwareInterface>hardware_interface/EffortJointInterface</hardwareInterface>
    </joint>
    <actuator name="wheel2_steering_joint_motor">
      <hardwareInterface>hardware_interface/EffortJointInterface</hardwareInterface>
      <mechanicalReduction>504</mechanicalReduction>
    </actuator>
  </transmission>
  <joint name="wheel2_wheel_modular_joint" type="fixed">
    <origin rpy="0 0 0" xyz="-0.142143 0 -0.229872"/>
    <parent link="wheel2_suspension_link"/>
    <child link="wheel2_steering_link"/>
  </joint>
  <link name="wheel2_wheel_link">
    <inertial>
      <origin rpy="0 0 0" xyz="0 0 0.000083"/>
      <mass value="3.2532"/>
      <inertia ixx="0.999544" ixy="-0.030190" ixz="0.000003" iyy="0.999544" iyz="0.000095" izz="1.0"/>
    </inertial>
    <visual>
      <origin rpy="0 0 0" xyz="0 0 0"/>
      <geometry>
        <mesh filename="package://flowerbot_description/meshes/wheel_link.STL"/>
      </geometry>
      <material name="material_black"/>
    </visual>
    <collision>
      <origin rpy="0 0 0" xyz="0 0 0"/>
      <geometry>
        <mesh filename="package://flowerbot_description/meshes/wheel_link.STL"/>
      </geometry>
    </collision>
  </link>
  <joint name="wheel2_driving_joint" type="continuous">
    <origin rpy="-1.57079632679 0 0" xyz="0 0.007981 -0.18"/>
    <parent link="wheel2_steering_arm_link"/>
    <child link="wheel2_wheel_link"/>
    <axis xyz="0 -1 0"/>
    <safety_controller k_velocity="5"/>
  </joint>
  <transmission name="wheel2_driving_joint_control">
    <type>transmission_interface/SimpleTransmission</type>
    <joint name="wheel2_driving_joint">
      <hardwareInterface>hardware_interface/EffortJointInterface</hardwareInterface>
    </joint>
    <actuator name="wheel2_driving_joint_motor">
      <hardwareInterface>hardware_interface/EffortJointInterface</hardwareInterface>
      <mechanicalReduction>84</mechanicalReduction>
    </actuator>
  </transmission>
  <gazebo reference="wheel3_suspension_link">
    <mu1>0</mu1>
    <mu2>0</mu2>
    <kp>1000000.0</kp>
    <kd>100.0</kd>
    <material>Gazebo/Blue</material>
  </gazebo>
  <link name="wheel3_suspension_link">
    <inertial>
      <origin rpy="0 0 0" xyz="-0.033779  -0.000046 -0.112357"/>
      <mass value="0.27606"/>
      <inertia ixx="0.058272" ixy="-0.000542" ixz="0.998301" iyy="0.001418" iyz="-0.058272" izz="0.000624"/>
    </inertial>
    <visual>
      <origin rpy="0 0 0" xyz="0 0 0"/>
      <geometry>
        <mesh filename="package://flowerbot_description/meshes/suspension_link.STL"/>
      </geometry>
      <material name="material_blue"/>
    </visual>
    <collision>
      <origin rpy="0 0 0" xyz="0 0 0"/>
      <geometry>
        <mesh filename="package://flowerbot_description/meshes/suspension_link.STL"/>
      </geometry>
    </collision>
  </link>
  <joint name="wheel3_suspension_joint" type="fixed">
    <origin rpy="0 0 0" xyz="-0.3048 -0.29195 0.21"/>
    <parent link="base_link"/>
    <child link="wheel3_suspension_link"/>
  </joint>
  <gazebo reference="wheel3_steering_link">
    <mu1>0</mu1>
    <mu2>0</mu2>
    <kp>1000000.0</kp>
    <kd>100.0</kd>
    <material>Gazebo/Orange</material>
  </gazebo>
  <gazebo reference="wheel3_steering_arm_link">
    <mu1>0</mu1>
    <mu2>0</mu2>
    <kp>1000000.0</kp>
    <kd>100.0</kd>
    <material>Gazebo/Orange</material>
  </gazebo>
  <gazebo reference="wheel3_wheel_link">
    <mu1>1</mu1>
    <mu2>1</mu2>
    <kp>1000000.0</kp>
    <kd>100.0</kd>
    <material>Gazebo/Black</material>
  </gazebo>
  <link name="wheel3_steering_arm_link">
    <inertial>
      <origin rpy="0 0 0" xyz="-0.000033 -0.059005  -0.107760"/>
      <mass value="0.64615"/>
      <inertia ixx="-0.00075" ixy="0.234166" ixz="0.972196" iyy="-0.972192" iyz="0.234167" izz="0.00008"/>
    </inertial>
    <visual>
      <origin rpy="0 0 0" xyz="0 0 0"/>
      <geometry>
        <mesh filename="package://flowerbot_description/meshes/steering_arm_link.STL"/>
      </geometry>
      <material name="material_orange"/>
    </visual>
    <collision>
      <origin rpy="0 0 0" xyz="0 0 0"/>
      <geometry>
        <mesh filename="package://flowerbot_description/meshes/steering_arm_link.STL"/>
      </geometry>
    </collision>
  </link>
  <link name="wheel3_steering_link">
    <inertial>
      <origin rpy="0 0 0" xyz="0.004891 0 0.053105"/>
      <mass value="0.49153"/>
      <inertia ixx="-0.004791" ixy="0" ixz="0.999989" iyy="0.000" iyz="0.004791" izz="0"/>
    </inertial>
    <visual>
      <origin rpy="0 0 0" xyz="0 0 0"/>
      <geometry>
        <mesh filename="package://flowerbot_description/meshes/steering_link.STL"/>
      </geometry>
      <material name="material_orange"/>
    </visual>
    <collision>
      <origin rpy="0 0 0" xyz="0 0 0"/>
      <geometry>
        <mesh filename="package://flowerbot_description/meshes/steering_link.STL"/>
      </geometry>
    </collision>
  </link>
  <joint name="wheel3_steering_joint" type="revolute">
    <origin rpy="0 0 0" xyz="0 0 -0.001"/>
    <parent link="wheel3_steering_link"/>
    <child link="wheel3_steering_arm_link"/>
    <axis xyz="0 0 1"/>
    <limit effort="0" lower="-1.57079632679" upper="1.57079632679" velocity="1"/>
    <safety_controller k_velocity="0"/>
  </joint>
  <transmission name="wheel3_steering_joint_control">
    <type>transmission_interface/SimpleTransmission</type>
    <joint name="wheel3_steering_joint">
      <hardwareInterface>hardware_interface/EffortJointInterface</hardwareInterface>
    </joint>
    <actuator name="wheel3_steering_joint_motor">
      <hardwareInterface>hardware_interface/EffortJointInterface</hardwareInterface>
      <mechanicalReduction>504</mechanicalReduction>
    </actuator>
  </transmission>
  <joint name="wheel3_wheel_modular_joint" type="fixed">
    <origin rpy="0 0 0" xyz="-0.142143 0 -0.229872"/>
    <parent link="wheel3_suspension_link"/>
    <child link="wheel3_steering_link"/>
  </joint>
  <link name="wheel3_wheel_link">
    <inertial>
      <origin rpy="0 0 0" xyz="0 0 0.000083"/>
      <mass value="3.2532"/>
      <inertia ixx="0.999544" ixy="-0.030190" ixz="0.000003" iyy="0.999544" iyz="0.000095" izz="1.0"/>
    </inertial>
    <visual>
      <origin rpy="0 0 0" xyz="0 0 0"/>
      <geometry>
        <mesh filename="package://flowerbot_description/meshes/wheel_link.STL"/>
      </geometry>
      <material name="material_black"/>
    </visual>
    <collision>
      <origin rpy="0 0 0" xyz="0 0 0"/>
      <geometry>
        <mesh filename="package://flowerbot_description/meshes/wheel_link.STL"/>
      </geometry>
    </collision>
  </link>
  <joint name="wheel3_driving_joint" type="continuous">
    <origin rpy="-1.57079632679 0 0" xyz="0 0.007981 -0.18"/>
    <parent link="wheel3_steering_arm_link"/>
    <child link="wheel3_wheel_link"/>
    <axis xyz="0 -1 0"/>
    <safety_controller k_velocity="5"/>
  </joint>
  <transmission name="wheel3_driving_joint_control">
    <type>transmission_interface/SimpleTransmission</type>
    <joint name="wheel3_driving_joint">
      <hardwareInterface>hardware_interface/EffortJointInterface</hardwareInterface>
    </joint>
    <actuator name="wheel3_driving_joint_motor">
      <hardwareInterface>hardware_interface/EffortJointInterface</hardwareInterface>
      <mechanicalReduction>84</mechanicalReduction>
    </actuator>
  </transmission>
  <gazebo>
    <plugin filename="libgazebo_ros_control.so" name="gazebo_ros_control">
      <robotNamespace>/flowerbot</robotNamespace>
      <robotParam>/robot_description</robotParam>
      <robotSimType>gazebo_ros_control/DefaultRobotHWSim</robotSimType>
    </plugin>
  </gazebo>
</robot>
